Workbook

Sheet Read_Me
A1: Portfolio Project – Sales Performance & MIS Dashboard
A3: Project objective: demonstrate Excel data cleaning, formula-driven transformation, KPI reporting, and dashboarding for an MIS/Data Analyst role.
A4: Workflow: Raw_Data -> Cleaned_Data (formula-based) -> Excel_Dashboard.
A5: Raw_Data intentionally contains inconsistent capitalization, spaces, alternate city names, missing values, invalid quantities/prices, mixed date formats, and duplicate order IDs.
A6: Cleaning is formula-driven. Key formulas use TRIM, PROPER, IFERROR, IF, MAX, VALUE, DATEVALUE, SUMIFS, COUNTIF, and EDATE.
A7: Calculated business metrics: Gross Sales, Discount Amount, Net Sales, Estimated Cost, Profit, Profit Margin, and Order Month.
A8: Quality checks updated: duplicate Order_ID values are flagged in Cleaned_Data; common city-name variants are standardized.
A9: Dashboard KPI formulas: Profit Margin = Total Profit / Net Sales; Average Order Value = Net Sales / Total Orders.
A10: Note: non-positive quantities are floored to zero in the cleaned calculation and flagged as CHECK. Estimated costs use illustrative category assumptions.

Sheet Raw_Data
A1: Order_ID | B1: Order_Date | C1: Salesperson | D1: City | E1: Sales_Channel | F1: Customer_Segment | G1: Category | H1: Product | I1: Quantity | J1: Unit_Price | K1: Discount | L1: Order_Status
A2: ORD-10001 | B2: 13/06/2026 | C2: Ravi | D2: Mumbai | E2: Online | F2: Consumer | G2: Laptop | H2: Laptop Pro 14 | I2: -1 | J2: 61049 | K2: 0.1 | L2: Pending
A3: ORD-10002 | B3: 2026-07-15 | C3: Ravi | D3: chennai | E3: Corporate | F3: Consumer | G3: Keyboard | H3: Keyboard Wireless | I3: 5 | J3: 4140 | K3: 0 | L3: Returned
A4: ORD-10003 | B4: 2026-01-26 | C4: Priya | D4: MYSURU | E4: Retail Store | F4: Consumer | G4: Mouse | H4: Mouse Ergonomic | I4: 5 | J4: 2155 | K4: 0.15 | L4: Returned
A5: ORD-10004 | B5: 24/02/2026 | C5: Bhoomika | D5: DELHI | E5: Corporate | F5: SMB | G5: Headset | H5: Headset Office | I5: 3 | J5: 5258 | K5: 0.05 | L5: Delivered
A6: ORD-10005 | B6: 2026-01-17 | C6: Arjun | D6: mysuru | E6: retail store | F6: Consumer | G6: Mouse | H6: Mouse Ergonomic | I6: 2 | J6: 3486 | K6: 0.15 | L6: Cancelled
A7: ORD-10006 | B7: 2026-02-20 | C7: Bhoomika | D7: Hyderabad | E7: Corporate | F7: SMB | G7: Monitor | H7: Monitor 27 | I7: 8 | J7: 26378 | K7: 0 | L7: Delivered
A8: ORD-10007 | B8: 05/06/2026 | C8: arjun | D8: Pune | E8: Corporate | F8: SMB | G8: Mouse | H8: Mouse Wireless | I8: 8 | J8: 2494 | K8: 0 | L8: Delivered
A9: ORD-10008 | B9: 2026-02-03 | C9: Kiran | D9: Mysore | E9: Corporate | F9: Consumer | G9: Headset | H9: Headset Office | I9: 2 | J9: 2272 | K9: 0.15 | L9: Pending
A10: ORD-10009 | B10: 2026-04-29 | C10: Neha | D10: mysuru | E10: Online | F10: SMB | G10: Monitor | H10: Monitor 24 | I10: 1 | J10: 12208 | K10: 0 | L10: Delivered
A11: ORD-10010 | B11: 05/05/2026 | C11: priya | D11: MUMBAI | E11: Online | F11: SMB | G11: Monitor | H11: Monitor 24 | I11: 1 | J11: 10916 | K11: 0.1 | L11: Pending
A12: ORD-10011 | B12: 25/05/2026 | C12: Arjun | D12: Mumbai | E12: Online | F12: Consumer | G12: Headset | H12: Headset Wireless | I12: 3 | J12: 4742 | K12: 0.15 | L12: Returned
A13: ORD-10012 | B13: 23/04/2026 | C13: Priya | D13: mumbai | E13: Corporate | F13: Consumer | G13: Headset | H13: Headset Office | I13: 3 | J13: 2348 | K13: 0.05 | L13: Delivered
... A24: ORD-10023 | B24: 2026-06-01 | C24: arjun | D24: Mumbai | E24: Retail Store | F24: Enterprise | G24: Monitor | H24: Monitor 24 | I24: 7 | J24: 12966 | K24: 0.15 | L24: Delivered
A25: ORD-10024 | B25: 04/05/2026 | C25: Kiran | D25: mumbai | E25: Retail Store | F25: SMB | G25: Mouse | H25: Mouse Ergonomic | I25: 4 | K25: 0.08 | L25: Cancelled
A26: ORD-10025 | B26: 04/07/2026 | C26: Bhoomika | D26: pune | E26: Corporate | F26: Enterprise | G26: Mouse | H26: Mouse Ergonomic | I26: 5 | J26: 770 | K26: 0.02 | L26: Pending
A27: ORD-10026 | B27: 2026-07-15 | C27: Priya | D27: PUNE | E27: Online | F27: SMB | G27: Monitor | H27: Monitor 24 | I27: -2 | J27: 18060 | K27: 0.02 | L27: Delivered
A28: ORD-10027 | B28: 2026-01-14 | C28: Bhoomika | D28: CHENNAI | E28: Corporate | F28: Consumer | G28: Keyboard | H28: Keyboard Mechanical | I28: 1 | J28: 5228 | K28: 0.02 | L28: Delivered
A29: ORD-10028 | B29: 2026-01-16 | C29: priya | D29: chennai | E29: Corporate | F29: SMB | G29: Headset | H29: Headset Office | I29: 3 | J29: 2165 | K29: 0.02 | L29: Delivered
A30: ORD-10029 | B30: 28/08/2026 | C30: Bhoomika | D30: Chennai | E30: Retail Store | F30: Enterprise | G30: Monitor | H30: Monitor 27 | I30: 2 | J30: 16366 | K30: 0 | L30: Delivered
A31: ORD-10030 | B31: 2026-06-22 | C31: Kiran | D31: Bengaluru | E31: Online | F31: Enterprise | G31: Headset | H31: Headset Office | I31: 8 | J31: 5354 | K31: 0.05 | L31: Delivered
A32: ORD-10031 | B32: 2026-04-27 | C32: Arjun | D32: MUMBAI | E32: Retail Store | F32: SMB | G32: Laptop | H32: Laptop Air 13 | I32: 8 | J32: 66186 | K32: 0.08 | L32: Delivered
A33: ORD-10032 | B33: 10/02/2026 | C33: Neha | D33: bengaluru | E33: Corporate | F33: Enterprise | G33: Keyboard | H33: Keyboard Office | I33: 8 | J33: 1963 | K33: 0 | L33: Returned
A34: ORD-10033 | B34: 2026-07-17 | C34: Arjun | D34: MUMBAI | E34: Retail Store | F34: Enterprise | G34: Mouse | H34: Mouse Ergonomic | I34: 8 | J34: 3104 | K34: 0.02 | L34: Pending
A35: ORD-10034 | B35: 2026-04-09 | C35: Priya | D35: Bangalore | E35: Online | F35: Enterprise | G35: Monitor | H35: Monitor 27 | I35: 2 | J35: 25459 | K35: 0.1 | L35: Pending
A36: ORD-10035 | B36: 14/07/2026 | C36: Ravi | D36: BENGALURU | E36: online | F36: SMB | G36: Mouse | H36: Mouse Basic | I36: 7 | J36: 1631 | K36: 0 | L36: Returned
A37: ORD-10036 | B37: 2026-04-08 | C37: Neha | D37: pune | E37: Online | F37: Enterprise | G37: Headset | H37: Headset Office | I37: 5 | J37: 6725 | K37: 0.08 | L37: Delivered
... A53: ORD-10052 | B53: 29/03/2026 | C53: Kiran | D53: Hyderabad | E53: corporate | F53: Consumer | G53: Laptop | H53: Business Laptop 15 | I53: 3 | J53: 47565 | K53: 0.05 | L53: Delivered
A54: ORD-10053 | C54: Arjun | D54: Hydrabad | E54: Corporate | F54: Consumer | G54: Keyboard | H54: Keyboard Wireless | I54: 2 | J54: 4410 | K54: 0.05 | L54: Cancelled
A55: ORD-10054 | B55: 2026-02-05 | C55: Priya | D55: MUMBAI | E55: Online | F55: SMB | G55: Monitor | H55: Monitor 24 | I55: 3 | J55: 25635 | K55: 0.1 | L55: Pending
A56: ORD-10055 | B56: 20/07/2026 | C56: Priya | D56: Delhi | E56: Retail Store | F56: Consumer | G56: Mouse | H56: Mouse Wireless | I56: 7 | J56: 1854 | K56: 0.02 | L56: Delivered
A57: ORD-10056 | B57: 2026-02-26 | C57: Asha | D57: BENGALURU | E57: Corporate | F57: SMB | G57: Mouse | H57: Mouse Ergonomic | I57: 4 | J57: 2756 | K57: 0.08 | L57: Delivered
A58: ORD-10057 | B58: 2026-01-05 | C58: Kiran | D58: Hyderabad | E58: Online | F58: Enterprise | G58: Keyboard | H58: Keyboard Wireless | I58: 4 | K58: 0.05 | L58: Delivered
A59: ORD-10058 | B59: 2026-02-17 | C59: Kiran | D59: Delhi | E59: Online | F59: SMB | G59: Laptop | H59: Business Laptop 15 | I59: 1 | J59: 49435 | K59: 0.08 | L59: Pending
A60: ORD-10059 | B60: 2026-07-19 | C60: Asha | D60: Mysuru | E60: Retail Store | F60: Consumer | G60: Mouse | H60: Mouse Basic | I60: 5 | J60: 2574 | K60: 0.02 | L60: Delivered
A61: ORD-10060 | B61: 05/04/2026 | C61: Ravi | D61: mysuru | E61: Corporate | F61: SMB | G61: Mouse | H61: Mouse Ergonomic | I61: 8 | J61: 2732 | K61: 0.05 | L61: Cancelled
A62: ORD-10061 | B62: 25/04/2026 | C62: Priya | D62: Delhi | E62: Corporate | F62: Enterprise | G62: Laptop | H62: Business Laptop 15 | I62: 7 | J62: 73504 | K62: 0.05 | L62: Cancelled
A63: ORD-10062 | B63: 2026-04-05 | C63: Priya | D63: CHENNAI | E63: Corporate | F63: Enterprise | G63: Keyboard | H63: Keyboard Mechanical | I63: 5 | J63: 4206 | K63: 0.02 | L63: Delivered
A64: ORD-10063 | B64: 2026-08-19 | C64: Meghana | D64: New Delhi | E64: retail store | F64: Consumer | G64: Mouse | H64: Mouse Wireless | I64: 3 | J64: 1928 | K64: 0.05 | L64: Cancelled
A65: ORD-10064 | B65: 15/05/2026 | C65: Priya | D65: CHENNAI | E65: Corporate | F65: SMB | G65: Mouse | H65: Mouse Ergonomic | I65: 6 | J65: 2543 | K65: 0.02 | L65: Cancelled
...

Sheet Cleaned_Data
A1: Order_ID | B1: Order_Date | C1: Salesperson | D1: City | E1: Sales_Channel | F1: Customer_Segment | G1: Category | H1: Product | I1: Quantity | J1: Unit_Price | K1: Discount | L1: Order_Status | M1: Gross_Sales | N1: Discount_Amount | O1: Net_Sales | P1: Estimated_Cost | Q1: Profit | R1: Profit_Margin | S1: Order_Month | T1: Data_Quality_Flag
A2: =TRIM(Raw_Data!A2) -> ORD-10001 | B2: =IFERROR(IF(ISNUMBER(Raw_Data!B2),Raw_Data!B2,DATEVALUE(Raw_Data!B2)),"") -> 46186 | C2: =PROPER(TRIM(Raw_Data!C2)) -> Ravi | D2: =IF(TRIM(Raw_Data!D2)="Bangalore","Bengaluru",IF(TRIM(Raw_Data!D2)="Mysore","Mysuru",IF(TRIM(Raw_Data!D2)="Cochin","Kochi",PROPER(TRIM(Raw_Data!D2))))) -> Mumbai | E2: =PROPER(TRIM(Raw_Data!E2)) -> Online | F2: =PROPER(TRIM(Raw_Data!F2)) -> Consumer | G2: =PROPER(TRIM(Raw_Data!G2)) -> Laptop | H2: =PROPER(TRIM(Raw_Data!H2)) -> Laptop Pro 14 | I2: =IFERROR(MAX(0,VALUE(Raw_Data!I2)),0) -> 0 | J2: =IFERROR(VALUE(Raw_Data!J2),0) -> 61049 | K2: =IFERROR(VALUE(Raw_Data!K2),0) -> 0.1 | L2: =PROPER(TRIM(Raw_Data!L2)) -> Pending | M2: =I2*J2 -> 0 | N2: =M2*K2 -> 0 | O2: =M2-N2 -> 0 | P2: =M2*IF(G2="Laptop",0.78,IF(G2="Monitor",0.7,IF(G2="Keyboard",0.58,IF(G2="Mouse",0.55,0.6)))) -> 0 | Q2: =O2-P2 -> 0 | R2: =IFERROR(Q2/O2,0) -> 0 | S2: =IF(B2="","",TEXT(B2,"mmm-yyyy")) -> Jun-2026 | T2: =IF(OR(A2="",B2="",I2<=0,J2<=0,L2=""),"CHECK","OK") -> CHECK
A3: =TRIM(Raw_Data!A3) -> ORD-10002 | B3: =IFERROR(IF(ISNUMBER(Raw_Data!B3),Raw_Data!B3,DATEVALUE(Raw_Data!B3)),"") -> 46218 | C3: =PROPER(TRIM(Raw_Data!C3)) -> Ravi | D3: =IF(TRIM(Raw_Data!D3)="Bangalore","Bengaluru",IF(TRIM(Raw_Data!D3)="Mysore","Mysuru",IF(TRIM(Raw_Data!D3)="Cochin","Kochi",PROPER(TRIM(Raw_Data!D3))))) -> Chennai | E3: =PROPER(TRIM(Raw_Data!E3)) -> Corporate | F3: =PROPER(TRIM(Raw_Data!F3)) -> Consumer | G3: =PROPER(TRIM(Raw_Data!G3)) -> Keyboard | H3: =PROPER(TRIM(Raw_Data!H3)) -> Keyboard Wireless | I3: =IFERROR(MAX(0,VALUE(Raw_Data!I3)),0) -> 5 | J3: =IFERROR(VALUE(Raw_Data!J3),0) -> 4140 | K3: =IFERROR(VALUE(Raw_Data!K3),0) -> 0 | L3: =PROPER(TRIM(Raw_Data!L3)) -> Returned | M3: =I3*J3 -> 20700 | N3: =M3*K3 -> 0 | O3: =M3-N3 -> 20700 | P3: =M3*IF(G3="Laptop",0.78,IF(G3="Monitor",0.7,IF(G3="Keyboard",0.58,IF(G3="Mouse",0.55,0.6)))) -> 12006 | Q3: =O3-P3 -> 8694 | R3: =IFERROR(Q3/O3,0) -> 0.42 | S3: =IF(B3="","",TEXT(B3,"mmm-yyyy")) -> Jul-2026 | T3: =IF(OR(A3="",B3="",I3<=0,J3<=0,L3=""),"CHECK","OK") -> OK
A4: =TRIM(Raw_Data!A4) -> ORD-10003 | B4: =IFERROR(IF(ISNUMBER(Raw_Data!B4),Raw_Data!B4,DATEVALUE(Raw_Data!B4)),"") -> 46048 | C4: =PROPER(TRIM(Raw_Data!C4)) -> Priya | D4: =IF(TRIM(Raw_Data!D4)="Bangalore","Bengaluru",IF(TRIM(Raw_Data!D4)="Mysore","Mysuru",IF(TRIM(Raw_Data!D4)="Cochin","Kochi",PROPER(TRIM(Raw_Data!D4))))) -> Mysuru | E4: =PROPER(TRIM(Raw_Data!E4)) -> Retail Store | F4: =PROPER(TRIM(Raw_Data!F4)) -> Consumer | G4: =PROPER(TRIM(Raw_Data!G4)) -> Mouse | H4: =PROPER(TRIM(Raw_Data!H4)) -> Mouse Ergonomic | I4: =IFERROR(MAX(0,VALUE(Raw_Data!I4)),0) -> 5 | J4: =IFERROR(VALUE(Raw_Data!J4),0) -> 2155 | K4: =IFERROR(VALUE(Raw_Data!K4),0) -> 0.15 | L4: =PROPER(TRIM(Raw_Data!L4)) -> Returned | M4: =I4*J4 -> 10775 | N4: =M4*K4 -> 1616.25 | O4: =M4-N4 -> 9158.75 | P4: =M4*IF(G4="Laptop",0.78,IF(G4="Monitor",0.7,IF(G4="Keyboard",0.58,IF(G4="Mouse",0.55,0.6)))) -> 5926.25 | Q4: =O4-P4 -> 3232.5 | R4: =IFERROR(Q4/O4,0) -> 0.35294118 | S4: =IF(B4="","",TEXT(B4,"mmm-yyyy")) -> Jan-2026 | T4: =IF(OR(A4="",B4="",I4<=0,J4<=0,L4=""),"CHECK","OK") -> OK
A5: =TRIM(Raw_Data!A5) -> ORD-10004 | B5: =IFERROR(IF(ISNUMBER(Raw_Data!B5),Raw_Data!B5,DATEVALUE(Raw_Data!B5)),"") -> 46077 | C5: =PROPER(TRIM(Raw_Data!C5)) -> Bhoomika | D5: =IF(TRIM(Raw_Data!D5)="Bangalore","Bengaluru",IF(TRIM(Raw_Data!D5)="Mysore","Mysuru",IF(TRIM(Raw_Data!D5)="Cochin","Kochi",PROPER(TRIM(Raw_Data!D5))))) -> Delhi | E5: =PROPER(TRIM(Raw_Data!E5)) -> Corporate | F5: =PROPER(TRIM(Raw_Data!F5)) -> Smb | G5: =PROPER(TRIM(Raw_Data!G5)) -> Headset | H5: =PROPER(TRIM(Raw_Data!H5)) -> Headset Office | I5: =IFERROR(MAX(0,VALUE(Raw_Data!I5)),0) -> 3 | J5: =IFERROR(VALUE(Raw_Data!J5),0) -> 5258 | K5: =IFERROR(VALUE(Raw_Data!K5),0) -> 0.05 | L5: =PROPER(TRIM(Raw_Data!L5)) -> Delivered | M5: =I5*J5 -> 15774 | N5: =M5*K5 -> 788.7 | O5: =M5-N5 -> 14985.3 | P5: =M5*IF(G5="Laptop",0.78,IF(G5="Monitor",0.7,IF(G5="Keyboard",0.58,IF(G5="Mouse",0.55,0.6)))) -> 9464.4 | Q5: =O5-P5 -> 5520.9 | R5: =IFERROR(Q5/O5,0) -> 0.36842105 | S5: =IF(B5="","",TEXT(B5,"mmm-yyyy")) -> Feb-2026 | T5: =IF(OR(A5="",B5="",I5<=0,J5<=0,L5=""),"CHECK","OK") -> OK
A6: =TRIM(Raw_Data!A6) -> ORD-10005 | B6: =IFERROR(IF(ISNUMBER(Raw_Data!B6),Raw_Data!B6,DATEVALUE(Raw_Data!B6)),"") -> 46039 | C6: =PROPER(TRIM(Raw_Data!C6)) -> Arjun | D6: =IF(TRIM(Raw_Data!D6)="Bangalore","Bengaluru",IF(TRIM(Raw_Data!D6)="Mysore","Mysuru",IF(TRIM(Raw_Data!D6)="Cochin","Kochi",PROPER(TRIM(Raw_Data!D6))))) -> Mysuru | E6: =PROPER(TRIM(Raw_Data!E6)) -> Retail Store | F6: =PROPER(TRIM(Raw_Data!F6)) -> Consumer | G6: =PROPER(TRIM(Raw_Data!G6)) -> Mouse | H6: =PROPER(TRIM(Raw_Data!H6)) -> Mouse Ergonomic | I6: =IFERROR(MAX(0,VALUE(Raw_Data!I6)),0) -> 2 | J6: =IFERROR(VALUE(Raw_Data!J6),0) -> 3486 | K6: =IFERROR(VALUE(Raw_Data!K6),0) -> 0.15 | L6: =PROPER(TRIM(Raw_Data!L6)) -> Cancelled | M6: =I6*J6 -> 6972 | N6: =M6*K6 -> 1045.8 | O6: =M6-N6 -> 5926.2 | P6: =M6*IF(G6="Laptop",0.78,IF(G6="Monitor",0.7,IF(G6="Keyboard",0.58,IF(G6="Mouse",0.55,0.6)))) -> 3834.6 | Q6: =O6-P6 -> 2091.6 | R6: =IFERROR(Q6/O6,0) -> 0.35294118 | S6: =IF(B6="","",TEXT(B6,"mmm-yyyy")) -> Jan-2026 | T6: =IF(OR(A6="",B6="",I6<=0,J6<=0,L6=""),"CHECK","OK") -> OK
A7: =TRIM(Raw_Data!A7) -> ORD-10006 | B7: =IFERROR(IF(ISNUMBER(Raw_Data!B7),Raw_Data!B7,DATEVALUE(Raw_Data!B7)),"") -> 46073 | C7: =PROPER(TRIM(Raw_Data!C7)) -> Bhoomika | D7: =IF(TRIM(Raw_Data!D7)="Bangalore","Bengaluru",IF(TRIM(Raw_Data!D7)="Mysore","Mysuru",IF(TRIM(Raw_Data!D7)="Cochin","Kochi",PROPER(TRIM(Raw_Data!D7))))) -> Hyderabad | E7: =PROPER(TRIM(Raw_Data!E7)) -> Corporate | F7: =PROPER(TRIM(Raw_Data!F7)) -> Smb | G7: =PROPER(TRIM(Raw_Data!G7)) -> Monitor | H7: =PROPER(TRIM(Raw_Data!H7)) -> Monitor 27 | I7: =IFERROR(MAX(0,VALUE(Raw_Data!I7)),0) -> 8 | J7: =IFERROR(VALUE(Raw_Data!J7),0) -> 26378 | K7: =IFERROR(VALUE(Raw_Data!K7),0) -> 0 | L7: =PROPER(TRIM(Raw_Data!L7)) -> Delivered | M7: =I7*J7 -> 211024 | N7: =M7*K7 -> 0 | O7: =M7-N7 -> 211024 | P7: =M7*IF(G7="Laptop",0.78,IF(G7="Monitor",0.7,IF(G7="Keyboard",0.58,IF(G7="Mouse",0.55,0.6)))) -> 147716.8 | Q7: =O7-P7 -> 63307.2 | R7: =IFERROR(Q7/O7,0) -> 0.3 | S7: =IF(B7="","",TEXT(B7,"mmm-yyyy")) -> Feb-2026 | T7: =IF(OR(A7="",B7="",I7<=0,J7<=0,L7=""),"CHECK","OK") -> OK
A8: =TRIM(Raw_Data!A8) -> ORD-10007 | B8: =IFERROR(IF(ISNUMBER(Raw_Data!B8),Raw_Data!B8,DATEVALUE(Raw_Data!B8)),"") -> 46178 | C8: =PROPER(TRIM(Raw_Data!C8)) -> Arjun | D8: =IF(TRIM(Raw_Data!D8)="Bangalore","Bengaluru",IF(TRIM(Raw_Data!D8)="Mysore","Mysuru",IF(TRIM(Raw_Data!D8)="Cochin","Kochi",PROPER(TRIM(Raw_Data!D8))))) -> Pune | E8: =PROPER(TRIM(Raw_Data!E8)) -> Corporate | F8: =PROPER(TRIM(Raw_Data!F8)) -> Smb | G8: =PROPER(TRIM(Raw_Data!G8)) -> Mouse | H8: =PROPER(TRIM(Raw_Data!H8)) -> Mouse Wireless | I8: =IFERROR(MAX(0,VALUE(Raw_Data!I8)),0) -> 8 | J8: =IFERROR(VALUE(Raw_Data!J8),0) -> 2494 | K8: =IFERROR(VALUE(Raw_Data!K8),0) -> 0 | L8: =PROPER(TRIM(Raw_Data!L8)) -> Delivered | M8: =I8*J8 -> 19952 | N8: =M8*K8 -> 0 | O8: =M8-N8 -> 19952 | P8: =M8*IF(G8="Laptop",0.78,IF(G8="Monitor",0.7,IF(G8="Keyboard",0.58,IF(G8="Mouse",0.55,0.6)))) -> 10973.6 | Q8: =O8-P8 -> 8978.4 | R8: =IFERROR(Q8/O8,0) -> 0.45 | S8: =IF(B8="","",TEXT(B8,"mmm-yyyy")) -> Jun-2026 | T8: =IF(OR(A8="",B8="",I8<=0,J8<=0,L8=""),"CHECK","OK") -> OK
A9: =TRIM(Raw_Data!A9) -> ORD-10008 | B9: =IFERROR(IF(ISNUMBER(Raw_Data!B9),Raw_Data!B9,DATEVALUE(Raw_Data!B9)),"") -> 46056 | C9: =PROPER(TRIM(Raw_Data!C9)) -> Kiran | D9: =IF(TRIM(Raw_Data!D9)="Bangalore","Bengaluru",IF(TRIM(Raw_Data!D9)="Mysore","Mysuru",IF(TRIM(Raw_Data!D9)="Cochin","Kochi",PROPER(TRIM(Raw_Data!D9))))) -> Mysuru | E9: =PROPER(TRIM(Raw_Data!E9)) -> Corporate | F9: =PROPER(TRIM(Raw_Data!F9)) -> Consumer | G9: =PROPER(TRIM(Raw_Data!G9)) -> Headset | H9: =PROPER(TRIM(Raw_Data!H9)) -> Headset Office | I9: =IFERROR(MAX(0,VALUE(Raw_Data!I9)),0) -> 2 | J9: =IFERROR(VALUE(Raw_Data!J9),0) -> 2272 | K9: =IFERROR(VALUE(Raw_Data!K9),0) -> 0.15 | L9: =PROPER(TRIM(Raw_Data!L9)) -> Pending | M9: =I9*J9 -> 4544 | N9: =M9*K9 -> 681.6 | O9: =M9-N9 -> 3862.4 | P9: =M9*IF(G9="Laptop",0.78,IF(G9="Monitor",0.7,IF(G9="Keyboard",0.58,IF(G9="Mouse",0.55,0.6)))) -> 2726.4 | Q9: =O9-P9 -> 1136 | R9: =IFERROR(Q9/O9,0) -> 0.29411765 | S9: =IF(B9="","",TEXT(B9,"mmm-yyyy")) -> Feb-2026 | T9: =IF(OR(A9="",B9="",I9<=0,J9<=0,L9=""),"CHECK","OK") -> OK
A10: =TRIM(Raw_Data!A10) -> ORD-10009 | B10: =IFERROR(IF(ISNUMBER(Raw_Data!B10),Raw_Data!B10,DATEVALUE(Raw_Data!B10)),"") -> 46141 | C10: =PROPER(TRIM(Raw_Data!C10)) -> Neha | D10: =IF(TRIM(Raw_Data!D10)="Bangalore","Bengaluru",IF(TRIM(Raw_Data!D10)="Mysore","Mysuru",IF(TRIM(Raw_Data!D10)="Cochin","Kochi",PROPER(TRIM(Raw_Data!D10))))) -> Mysuru | E10: =PROPER(TRIM(Raw_Data!E10)) -> Online | F10: =PROPER(TRIM(Raw_Data!F10)) -> Smb | G10: =PROPER(TRIM(Raw_Data!G10)) -> Monitor | H10: =PROPER(TRIM(Raw_Data!H10)) -> Monitor 24 | I10: =IFERROR(MAX(0,VALUE(Raw_Data!I10)),0) -> 1 | J10: =IFERROR(VALUE(Raw_Data!J10),0) -> 12208 | K10: =IFERROR(VALUE(Raw_Data!K10),0) -> 0 | L10: =PROPER(TRIM(Raw_Data!L10)) -> Delivered | M10: =I10*J10 -> 12208 | N10: =M10*K10 -> 0 | O10: =M10-N10 -> 12208 | P10: =M10*IF(G10="Laptop",0.78,IF(G10="Monitor",0.7,IF(G10="Keyboard",0.58,IF(G10="Mouse",0.55,0.6)))) -> 8545.6 | Q10: =O10-P10 -> 3662.4 | R10: =IFERROR(Q10/O10,0) -> 0.3 | S10: =IF(B10="","",TEXT(B10,"mmm-yyyy")) -> Apr-2026 | T10: =IF(OR(A10="",B10="",I10<=0,J10<=0,L10=""),"CHECK","OK") -> OK
A11: =TRIM(Raw_Data!A11) -> ORD-10010 | B11: =IFERROR(IF(ISNUMBER(Raw_Data!B11),Raw_Data!B11,DATEVALUE(Raw_Data!B11)),"") -> 46147 | C11: =PROPER(TRIM(Raw_Data!C11)) -> Priya | D11: =IF(TRIM(Raw_Data!D11)="Bangalore","Bengaluru",IF(TRIM(Raw_Data!D11)="Mysore","Mysuru",IF(TRIM(Raw_Data!D11)="Cochin","Kochi",PROPER(TRIM(Raw_Data!D11))))) -> Mumbai | E11: =PROPER(TRIM(Raw_Data!E11)) -> Online | F11: =PROPER(TRIM(Raw_Data!F11)) -> Smb | G11: =PROPER(TRIM(Raw_Data!G11)) -> Monitor | H11: =PROPER(TRIM(Raw_Data!H11)) -> Monitor 24 | I11: =IFERROR(MAX(0,VALUE(Raw_Data!I11)),0) -> 1 | J11: =IFERROR(VALUE(Raw_Data!J11),0) -> 10916 | K11: =IFERROR(VALUE(Raw_Data!K11),0) -> 0.1 | L11: =PROPER(TRIM(Raw_Data!L11)) -> Pending | M11: =I11*J11 -> 10916 | N11: =M11*K11 -> 1091.6 | O11: =M11-N11 -> 9824.4 | P11: =M11*IF(G11="Laptop",0.78,IF(G11="Monitor",0.7,IF(G11="Keyboard",0.58,IF(G11="Mouse",0.55,0.6)))) -> 7641.2 | Q11: =O11-P11 -> 2183.2 | R11: =IFERROR(Q11/O11,0) -> 0.22222222 | S11: =IF(B11="","",TEXT(B11,"mmm-yyyy")) -> May-2026 | T11: =IF(OR(A11="",B11="",I11<=0,J11<=0,L11=""),"CHECK","OK") -> OK
A12: =TRIM(Raw_Data!A12) -> ORD-10011 | B12: =IFERROR(IF(ISNUMBER(Raw_Data!B12),Raw_Data!B12,DATEVALUE(Raw_Data!B12)),"") -> 46167 | C12: =PROPER(TRIM(Raw_Data!C12)) -> Arjun | D12: =IF(TRIM(Raw_Data!D12)="Bangalore","Bengaluru",IF(TRIM(Raw_Data!D12)="Mysore","Mysuru",IF(TRIM(Raw_Data!D12)="Cochin","Kochi",PROPER(TRIM(Raw_Data!D12))))) -> Mumbai | E12: =PROPER(TRIM(Raw_Data!E12)) -> Online | F12: =PROPER(TRIM(Raw_Data!F12)) -> Consumer | G12: =PROPER(TRIM(Raw_Data!G12)) -> Headset | H12: =PROPER(TRIM(Raw_Data!H12)) -> Headset Wireless | I12: =IFERROR(MAX(0,VALUE(Raw_Data!I12)),0) -> 3 | J12: =IFERROR(VALUE(Raw_Data!J12),0) -> 4742 | K12: =IFERROR(VALUE(Raw_Data!K12),0) -> 0.15 | L12: =PROPER(TRIM(Raw_Data!L12)) -> Returned | M12: =I12*J12 -> 14226 | N12: =M12*K12 -> 2133.9 | O12: =M12-N12 -> 12092.1 | P12: =M12*IF(G12="Laptop",0.78,IF(G12="Monitor",0.7,IF(G12="Keyboard",0.58,IF(G12="Mouse",0.55,0.6)))) -> 8535.6 | Q12: =O12-P12 -> 3556.5 | R12: =IFERROR(Q12/O12,0) -> 0.29411765 | S12: =IF(B12="","",TEXT(B12,"mmm-yyyy")) -> May-2026 | T12: =IF(OR(A12="",B12="",I12<=0,J12<=0,L12=""),"CHECK","OK") -> OK
A13: =TRIM(Raw_Data!A13) -> ORD-10012 | B13: =IFERROR(IF(ISNUMBER(Raw_Data!B13),Raw_Data!B13,DATEVALUE(Raw_Data!B13)),"") -> 46135 | C13: =PROPER(TRIM(Raw_Data!C13)) -> Priya | D13: =IF(TRIM(Raw_Data!D13)="Bangalore","Bengaluru",IF(TRIM(Raw_Data!D13)="Mysore","Mysuru",IF(TRIM(Raw_Data!D13)="Cochin","Kochi",PROPER(TRIM(Raw_Data!D13))))) -> Mumbai | E13: =PROPER(TRIM(Raw_Data!E13)) -> Corporate | F13: =PROPER(TRIM(Raw_Data!F13)) -> Consumer | G13: =PROPER(TRIM(Raw_Data!G13)) -> Headset | H13: =PROPER(TRIM(Raw_Data!H13)) -> Headset Office | I13: =IFERROR(MAX(0,VALUE(Raw_Data!I13)),0) -> 3 | J13: =IFERROR(VALUE(Raw_Data!J13),0) -> 2348 | K13: =IFERROR(VALUE(Raw_Data!K13),0) -> 0.05 | L13: =PROPER(TRIM(Raw_Data!L13)) -> Delivered | M13: =I13*J13 -> 7044 | N13: =M13*K13 -> 352.2 | O13: =M13-N13 -> 6691.8 | P13: =M13*IF(G13="Laptop",0.78,IF(G13="Monitor",0.7,IF(G13="Keyboard",0.58,IF(G13="Mouse",0.55,0.6)))) -> 4226.4 | Q13: =O13-P13 -> 2465.4 | R13: =IFERROR(Q13/O13,0) -> 0.36842105 | S13: =IF(B13="","",TEXT(B13,"mmm-yyyy")) -> Apr-2026 | T13: =IF(OR(A13="",B13="",I13<=0,J13<=0,L13=""),"CHECK","OK") -> OK
... A651: =TRIM(Raw_Data!A651) -> ORD-10650 | B651: =IFERROR(IF(ISNUMBER(Raw_Data!B651),Raw_Data!B651,DATEVALUE(Raw_Data!B651)),"") -> 46199 | C651: =PROPER(TRIM(Raw_Data!C651)) -> Bhoomika | D651: =IF(TRIM(Raw_Data!D651)="Bangalore","Bengaluru",IF(TRIM(Raw_Data!D651)="Mysore","Mysuru",IF(TRIM(Raw_Data!D651)="Cochin","Kochi",PROPER(TRIM(Raw_Data!D651))))) -> Mumbai | E651: =PROPER(TRIM(Raw_Data!E651)) -> Corporate | F651: =PROPER(TRIM(Raw_Data!F651)) -> Smb | G651: =PROPER(TRIM(Raw_Data!G651)) -> Headset | H651: =PROPER(TRIM(Raw_Data!H651)) -> Headset Office | I651: =IFERROR(MAX(0,VALUE(Raw_Data!I651)),0) -> 1 | J651: =IFERROR(VALUE(Raw_Data!J651),0) -> 5154 | K651: =IFERROR(VALUE(Raw_Data!K651),0) -> 0 | L651: =PROPER(TRIM(Raw_Data!L651)) -> Returned | M651: =I651*J651 -> 5154 | N651: =M651*K651 -> 0 | O651: =M651-N651 -> 5154 | P651: =M651*IF(G651="Laptop",0.78,IF(G651="Monitor",0.7,IF(G651="Keyboard",0.58,IF(G651="Mouse",0.55,0.6)))) -> 3092.4 | Q651: =O651-P651 -> 2061.6 | R651: =IFERROR(Q651/O651,0) -> 0.4 | S651: =IF(B651="","",TEXT(B651,"mmm-yyyy")) -> Jun-2026 | T651: =IF(OR(A651="",B651="",I651<=0,J651<=0,L651=""),"CHECK","OK") -> OK

Sheet Excel_Dashboard
A1: SALES PERFORMANCE DASHBOARD
A4: Total Orders | C4: Net Sales | E4: Profit | G4: Profit Margin | I4: Avg Order Value
A5: =COUNTA(Cleaned_Data!A2:A651) -> 650 | C5: =SUM(Cleaned_Data!O2:O651) -> 45625433 | E5: =SUM(Cleaned_Data!Q2:Q651) -> 9426744.3 | G5: =IFERROR(C13/C12,0) -> 1.444375 | I5: =IFERROR(C12/C11,0) -> 0.66300608
A9: Month | B9: Net Sales | C9: Profit | E9: Category | F9: Net Sales | H9: Salesperson | I9: Net Sales | K9: Order Status | L9: Orders
A10: 46023 | B10: =SUMIFS(Cleaned_Data!$O:$O,Cleaned_Data!$B:$B,">="&A10,Cleaned_Data!$B:$B,"<"&EDATE(A10,1)) -> 4885314.4 | C10: =SUMIFS(Cleaned_Data!$Q:$Q,Cleaned_Data!$B:$B,">="&A10,Cleaned_Data!$B:$B,"<"&EDATE(A10,1)) -> 996608.71 | E10: Laptop | F10: =SUMIFS(Cleaned_Data!$O:$O,Cleaned_Data!$G:$G,E10) -> 29762238 | H10: Asha | I10: =SUMIFS(Cleaned_Data!$O:$O,Cleaned_Data!$C:$C,H10) -> 5668604.5 | K10: Delivered | L10: =COUNTIF(Cleaned_Data!$L:$L,K10) -> 330
A11: 46054 | B11: =SUMIFS(Cleaned_Data!$O:$O,Cleaned_Data!$B:$B,">="&A11,Cleaned_Data!$B:$B,"<"&EDATE(A11,1)) -> 5712651.9 | C11: =SUMIFS(Cleaned_Data!$Q:$Q,Cleaned_Data!$B:$B,">="&A11,Cleaned_Data!$B:$B,"<"&EDATE(A11,1)) -> 1212031.4 | E11: Monitor | F11: =SUMIFS(Cleaned_Data!$O:$O,Cleaned_Data!$G:$G,E11) -> 10991984 | H11: Ravi | I11: =SUMIFS(Cleaned_Data!$O:$O,Cleaned_Data!$C:$C,H11) -> 5315515.9 | K11: Pending | L11: =COUNTIF(Cleaned_Data!$L:$L,K11) -> 95
A12: 46082 | B12: =SUMIFS(Cleaned_Data!$O:$O,Cleaned_Data!$B:$B,">="&A12,Cleaned_Data!$B:$B,"<"&EDATE(A12,1)) -> 3723352.9 | C12: =SUMIFS(Cleaned_Data!$Q:$Q,Cleaned_Data!$B:$B,">="&A12,Cleaned_Data!$B:$B,"<"&EDATE(A12,1)) -> 803584.17 | E12: Keyboard | F12: =SUMIFS(Cleaned_Data!$O:$O,Cleaned_Data!$G:$G,E12) -> 1585946.6 | H12: Priya | I12: =SUMIFS(Cleaned_Data!$O:$O,Cleaned_Data!$C:$C,H12) -> 6463421.5 | K12: Cancelled | L12: =COUNTIF(Cleaned_Data!$L:$L,K12) -> 108
A13: 46113 | B13: =SUMIFS(Cleaned_Data!$O:$O,Cleaned_Data!$B:$B,">="&A13,Cleaned_Data!$B:$B,"<"&EDATE(A13,1)) -> 5144270.2 | C13: =SUMIFS(Cleaned_Data!$Q:$Q,Cleaned_Data!$B:$B,">="&A13,Cleaned_Data!$B:$B,"<"&EDATE(A13,1)) -> 1160676.9 | E13: Mouse | F13: =SUMIFS(Cleaned_Data!$O:$O,Cleaned_Data!$G:$G,E13) -> 1278533.1 | H13: Meghana | I13: =SUMIFS(Cleaned_Data!$O:$O,Cleaned_Data!$C:$C,H13) -> 6143733.8 | K13: Returned | L13: =COUNTIF(Cleaned_Data!$L:$L,K13) -> 117
A14: 46143 | B14: =SUMIFS(Cleaned_Data!$O:$O,Cleaned_Data!$B:$B,">="&A14,Cleaned_Data!$B:$B,"<"&EDATE(A14,1)) -> 5441464.7 | C14: =SUMIFS(Cleaned_Data!$Q:$Q,Cleaned_Data!$B:$B,">="&A14,Cleaned_Data!$B:$B,"<"&EDATE(A14,1)) -> 1078937.4 | E14: Headset | F14: =SUMIFS(Cleaned_Data!$O:$O,Cleaned_Data!$G:$G,E14) -> 2006730.8 | H14: Bhoomika | I14: =SUMIFS(Cleaned_Data!$O:$O,Cleaned_Data!$C:$C,H14) -> 4553023.4
A15: 46174 | B15: =SUMIFS(Cleaned_Data!$O:$O,Cleaned_Data!$B:$B,">="&A15,Cleaned_Data!$B:$B,"<"&EDATE(A15,1)) -> 5502775.5 | C15: =SUMIFS(Cleaned_Data!$Q:$Q,Cleaned_Data!$B:$B,">="&A15,Cleaned_Data!$B:$B,"<"&EDATE(A15,1)) -> 1079226.6 | H15: Arjun | I15: =SUMIFS(Cleaned_Data!$O:$O,Cleaned_Data!$C:$C,H15) -> 5969906.3
A16: 46204 | B16: =SUMIFS(Cleaned_Data!$O:$O,Cleaned_Data!$B:$B,">="&A16,Cleaned_Data!$B:$B,"<"&EDATE(A16,1)) -> 9441698.2 | C16: =SUMIFS(Cleaned_Data!$Q:$Q,Cleaned_Data!$B:$B,">="&A16,Cleaned_Data!$B:$B,"<"&EDATE(A16,1)) -> 1890210.6 | H16: Kiran | I16: =SUMIFS(Cleaned_Data!$O:$O,Cleaned_Data!$C:$C,H16) -> 5233823.5
A17: 46235 | B17: =SUMIFS(Cleaned_Data!$O:$O,Cleaned_Data!$B:$B,">="&A17,Cleaned_Data!$B:$B,"<"&EDATE(A17,1)) -> 4511273.6 | C17: =SUMIFS(Cleaned_Data!$Q:$Q,Cleaned_Data!$B:$B,">="&A17,Cleaned_Data!$B:$B,"<"&EDATE(A17,1)) -> 967086.96 | H17: Neha | I17: =SUMIFS(Cleaned_Data!$O:$O,Cleaned_Data!$C:$C,H17) -> 6277403.8
A18: 46266 | B18: =SUMIFS(Cleaned_Data!$O:$O,Cleaned_Data!$B:$B,">="&A18,Cleaned_Data!$B:$B,"<"&EDATE(A18,1)) -> 0 | C18: =SUMIFS(Cleaned_Data!$Q:$Q,Cleaned_Data!$B:$B,">="&A18,Cleaned_Data!$B:$B,"<"&EDATE(A18,1)) -> 0
A36: Salesperson Performance
A37: Salesperson | B37: Net Sales | C37: Profit | D37: Margin
A38: Asha | B38: =SUMIFS(Cleaned_Data!$O:$O,Cleaned_Data!$C:$C,A38) -> 5668604.5 | C38: =SUMIFS(Cleaned_Data!$Q:$Q,Cleaned_Data!$C:$C,A38) -> 1138324.8 | D38: =IFERROR(C38/B38,0) -> 0.20081218
A39: Ravi | B39: =SUMIFS(Cleaned_Data!$O:$O,Cleaned_Data!$C:$C,A39) -> 5315515.9 | C39: =SUMIFS(Cleaned_Data!$Q:$Q,Cleaned_Data!$C:$C,A39) -> 1145024 | D39: =IFERROR(C39/B39,0) -> 0.21541164
A40: Priya | B40: =SUMIFS(Cleaned_Data!$O:$O,Cleaned_Data!$C:$C,A40) -> 6463421.5 | C40: =SUMIFS(Cleaned_Data!$Q:$Q,Cleaned_Data!$C:$C,A40) -> 1399030.8 | D40: =IFERROR(C40/B40,0) -> 0.21645359
A41: Meghana | B41: =SUMIFS(Cleaned_Data!$O:$O,Cleaned_Data!$C:$C,A41) -> 6143733.8 | C41: =SUMIFS(Cleaned_Data!$Q:$Q,Cleaned_Data!$C:$C,A41) -> 1225488.1 | D41: =IFERROR(C41/B41,0) -> 0.1994696
A42: Bhoomika | B42: =SUMIFS(Cleaned_Data!$O:$O,Cleaned_Data!$C:$C,A42) -> 4553023.4 | C42: =SUMIFS(Cleaned_Data!$Q:$Q,Cleaned_Data!$C:$C,A42) -> 984316 | D42: =IFERROR(C42/B42,0) -> 0.21618953
A43: Arjun | B43: =SUMIFS(Cleaned_Data!$O:$O,Cleaned_Data!$C:$C,A43) -> 5969906.3 | C43: =SUMIFS(Cleaned_Data!$Q:$Q,Cleaned_Data!$C:$C,A43) -> 1258063.9 | D43: =IFERROR(C43/B43,0) -> 0.21073427
A44: Kiran | B44: =SUMIFS(Cleaned_Data!$O:$O,Cleaned_Data!$C:$C,A44) -> 5233823.5 | C44: =SUMIFS(Cleaned_Data!$Q:$Q,Cleaned_Data!$C:$C,A44) -> 1045224.5 | D44: =IFERROR(C44/B44,0) -> 0.19970572
A45: Neha | B45: =SUMIFS(Cleaned_Data!$O:$O,Cleaned_Data!$C:$C,A45) -> 6277403.8 | C45: =SUMIFS(Cleaned_Data!$Q:$Q,Cleaned_Data!$C:$C,A45) -> 1231272.3 | D45: =IFERROR(C45/B45,0) -> 0.19614355
